#VRML_SIM R2021a utf8
WorldInfo {
  info [
    ""
  ]
  coordinateSystem "NUE"
}
Viewpoint {
  orientation -0.9998682286706337 -0.016159842623326162 -0.0015442737577561754 0.9970050402853948
  position 0.04358518941039084 3.180564023944151 1.971059811855287
  follow "e-puck"
}
TexturedBackground {
}
TexturedBackgroundLight {
}
RectangleArena {
  name "rectangle arena(1)"
  floorSize 10 10
  floorTileSize 2 2
  wallHeight 0.5
}
E-puck {
  translation 0.5 0 0.5
  rotation 0.010601265533916326 -0.9999437128145245 -0.000429385 0
  controller "using_gps"
  turretSlot [
    GPS {
      translation 0 0.00025 0
    }
    DistanceSensor {
      translation -7.34639e-08 -0.009 -0.04
      rotation 0 1 0 1.5708
      name "up_sensor"
      lookupTable [
        0 0 0
        10000 10000 0
      ]
    }
    DistanceSensor {
      translation 2.34464e-07 0.001 0.02
      rotation 0 1 0 -1.5707953071795862
      name "down_sensor"
      lookupTable [
        0 0 0
        10000 10000 0
      ]
    }
    DistanceSensor {
      translation 0.033 -0.006 -0.01
      rotation 0 -1 0 -5.307179586466759e-06
      name "right_sensor"
      lookupTable [
        0 0 0
        10000 10000 0
      ]
    }
    DistanceSensor {
      translation -0.033 -0.006 -0.00999973
      rotation 0 1 0 -3.1415853071795863
      name "left_sensor"
      lookupTable [
        0 0 0
        10000 10000 0
      ]
    }
    Camera {
      translation 0 0 -0.035
      name "colour_camera"
      recognitionColors [
        1 0 0
      ]
      fieldOfView 0.7854
      width 250
      height 250
      recognition Recognition {
      }
    }
  ]
  groundSensorsSlot [
    Compass {
      rotation 0 1 0 3.14159
    }
  ]
}
Robot {
  translation 3.39928 0 3.3687
  children [
    DEF laptop Laptop {
      rotation 0 1 0 3.14159
    }
  ]
  name "robot(1)"
  physics Physics {
  }
  recognitionColors [
    1 0 0
  ]
}
DEF mybot Robot {
  translation 0.49961 0.07 -1.1465
  children [
    DEF WHEEL HingeJoint {
      jointParameters HingeJointParameters {
        anchor 0.06 0 -0.05
      }
      device [
        RotationalMotor {
        }
      ]
      endPoint DEF Wheels Solid {
        translation 0.06 0 -0.05
        rotation 0 0 1 1.5708
        children [
          DEF Wheel Shape {
            appearance PBRAppearance {
              baseColor 1 1 0
            }
            geometry Cylinder {
              height 0.02
              radius 0.04
            }
          }
        ]
        name "solid(3)"
        boundingObject USE Wheel
        physics Physics {
        }
      }
    }
    DEF WHEEL HingeJoint {
      jointParameters HingeJointParameters {
        anchor 0.06 0 -0.05
      }
      device [
        RotationalMotor {
        }
      ]
      endPoint DEF Wheels Solid {
        translation -0.06 0 -0.05
        rotation 0 0 1 1.5708
        children [
          DEF Wheel Shape {
            appearance PBRAppearance {
              baseColor 1 1 0
            }
            geometry Cylinder {
              height 0.02
              radius 0.04
            }
          }
        ]
        name "solid(2)"
        boundingObject USE Wheel
        physics Physics {
        }
      }
    }
    DEF WHEEL HingeJoint {
      jointParameters HingeJointParameters {
        anchor 0.06 0 -0.05
      }
      device [
        RotationalMotor {
        }
      ]
      endPoint DEF Wheels Solid {
        translation -0.06 0 0.05
        rotation 0 0 1 1.5708
        children [
          DEF Wheel Shape {
            appearance PBRAppearance {
              baseColor 1 1 0
            }
            geometry Cylinder {
              height 0.02
              radius 0.04
            }
          }
        ]
        name "solid(1)"
        boundingObject USE Wheel
        physics Physics {
        }
      }
    }
    DEF WHEEL HingeJoint {
      jointParameters HingeJointParameters {
        anchor 0.06 0 -0.05
      }
      device [
        RotationalMotor {
        }
      ]
      endPoint DEF Wheels Solid {
        translation 0.06 0 0.05
        rotation 0 0 1 1.5708
        children [
          DEF Wheel Shape {
            appearance PBRAppearance {
              baseColor 1 1 0
            }
            geometry Cylinder {
              height 0.02
              radius 0.04
            }
          }
        ]
        boundingObject USE Wheel
        physics Physics {
        }
      }
    }
    DEF BODY Shape {
      appearance PBRAppearance {
        baseColor 1 0 1
      }
      geometry Box {
        size 0.1 0.03 0.2
      }
    }
  ]
  boundingObject USE BODY
  physics Physics {
  }
}
Wall {
  translation 1 0 4.5
  rotation 0 1 0 1.5708
  name "wall(3)"
  size 1 0.4 0.02
  appearance Roughcast {
    colorOverride 1 1 0
    textureTransform TextureTransform {
      scale 1 2.4
    }
  }
}
Wall {
  translation 1 0 3.5
  rotation 0 1 0 1.5708
  name "wall(8)"
  size 1 0.4 0.02
  appearance Roughcast {
    colorOverride 1 1 0
    textureTransform TextureTransform {
      scale 1 2.4
    }
  }
}
Wall {
  translation 1 0 0.5
  rotation 0 1 0 1.5708
  name "wall(18)"
  size 1 0.4 0.02
  appearance Roughcast {
    colorOverride 1 1 0
    textureTransform TextureTransform {
      scale 1 2.4
    }
  }
}
Wall {
  translation -1 0 -4.5
  rotation 0 1 0 1.5708
  name "wall(24)"
  size 1 0.4 0.02
  appearance Roughcast {
    colorOverride 1 1 0
    textureTransform TextureTransform {
      scale 1 2.4
    }
  }
}
Wall {
  translation -1 0 -3.5
  rotation 0 1 0 1.5708
  name "wall(25)"
  size 1 0.4 0.02
  appearance Roughcast {
    colorOverride 1 1 0
    textureTransform TextureTransform {
      scale 1 2.4
    }
  }
}
Wall {
  translation -1 0 -2.5
  rotation 0 1 0 1.5708
  name "wall(28)"
  size 1 0.4 0.02
  appearance Roughcast {
    colorOverride 1 1 0
    textureTransform TextureTransform {
      scale 1 2.4
    }
  }
}
Wall {
  translation 1 0 -2.5
  rotation 0 1 0 1.5708
  name "wall(29)"
  size 1 0.4 0.02
  appearance Roughcast {
    colorOverride 1 1 0
    textureTransform TextureTransform {
      scale 1 2.4
    }
  }
}
Wall {
  translation -1 0 3.5
  rotation 0 1 0 1.5708
  name "wall(5)"
  size 1 0.4 0.02
  appearance Roughcast {
    colorOverride 1 1 0
    textureTransform TextureTransform {
      scale 1 2.4
    }
  }
}
Wall {
  translation -1 0 0.5
  rotation 0 1 0 1.5708
  name "wall(15)"
  size 1 0.4 0.02
  appearance Roughcast {
    colorOverride 1 1 0
    textureTransform TextureTransform {
      scale 1 2.4
    }
  }
}
Wall {
  translation 3 0 -0.5
  rotation 0 1 0 1.5708
  name "wall(38)"
  size 1 0.4 0.02
  appearance Roughcast {
    colorOverride 1 1 0
    textureTransform TextureTransform {
      scale 1 2.4
    }
  }
}
Wall {
  translation 3 0 -4.5
  rotation 0 1 0 1.5708
  name "wall(42)"
  size 1 0.4 0.02
  appearance Roughcast {
    colorOverride 1 1 0
    textureTransform TextureTransform {
      scale 1 2.4
    }
  }
}
Wall {
  translation 3 0 -3.5
  rotation 0 1 0 1.5708
  name "wall(43)"
  size 1 0.4 0.02
  appearance Roughcast {
    colorOverride 1 1 0
    textureTransform TextureTransform {
      scale 1 2.4
    }
  }
}
Wall {
  translation 3 0 3.5
  rotation 0 1 0 1.5708
  name "wall(41)"
  size 1 0.4 0.02
  appearance Roughcast {
    colorOverride 1 1 0
    textureTransform TextureTransform {
      scale 1 2.4
    }
  }
}
Wall {
  translation -1 0 -0.5
  rotation 0 1 0 1.5708
  name "wall(31)"
  size 1 0.4 0.02
  appearance Roughcast {
    colorOverride 1 1 0
    textureTransform TextureTransform {
      scale 1 2.4
    }
  }
}
Wall {
  translation -4.5 0 3
  name "wall(1)"
  size 1 0.4 0.02
  appearance Roughcast {
    colorOverride 1 1 0
    textureTransform TextureTransform {
      scale 1 2.4
    }
  }
}
Wall {
  translation -1.5 0 4
  name "wall(4)"
  size 1 0.4 0.02
  appearance Roughcast {
    colorOverride 1 1 0
    textureTransform TextureTransform {
      scale 1 2.4
    }
  }
}
Wall {
  translation -3.5 0 0
  name "wall(11)"
  size 1 0.4 0.02
  appearance Roughcast {
    colorOverride 1 1 0
    textureTransform TextureTransform {
      scale 1 2.4
    }
  }
}
Wall {
  translation -3.5 0 -2
  name "wall(13)"
  size 1 0.4 0.02
  appearance Roughcast {
    colorOverride 1 1 0
    textureTransform TextureTransform {
      scale 1 2.4
    }
  }
}
Wall {
  translation -3.5 0 -4
  name "wall(21)"
  size 1 0.4 0.02
  appearance Roughcast {
    colorOverride 1 1 0
    textureTransform TextureTransform {
      scale 1 2.4
    }
  }
}
Wall {
  translation -0.5 0 3
  name "wall(6)"
  size 1 0.4 0.02
  appearance Roughcast {
    colorOverride 1 1 0
    textureTransform TextureTransform {
      scale 1 2.4
    }
  }
}
Wall {
  translation -0.5 0 1
  name "wall(17)"
  size 1 0.4 0.02
  appearance Roughcast {
    colorOverride 1 1 0
    textureTransform TextureTransform {
      scale 1 2.4
    }
  }
}
Wall {
  translation -0.5 0 -1
  name "wall(33)"
  size 1 0.4 0.02
  appearance Roughcast {
    colorOverride 1 1 0
    textureTransform TextureTransform {
      scale 1 2.4
    }
  }
}
Wall {
  translation -0.5 0 -2
  name "wall(26)"
  size 1 0.4 0.02
  appearance Roughcast {
    colorOverride 1 1 0
    textureTransform TextureTransform {
      scale 1 2.4
    }
  }
}
Wall {
  translation 0.5 0 -2
  name "wall(27)"
  size 1 0.4 0.02
  appearance Roughcast {
    colorOverride 1 1 0
    textureTransform TextureTransform {
      scale 1 2.4
    }
  }
}
Wall {
  translation 1.5 0 -3
  name "wall(30)"
  size 1 0.4 0.02
  appearance Roughcast {
    colorOverride 1 1 0
    textureTransform TextureTransform {
      scale 1 2.4
    }
  }
}
Wall {
  translation 0.5 0 1
  name "wall(16)"
  size 1 0.4 0.02
  appearance Roughcast {
    colorOverride 1 1 0
    textureTransform TextureTransform {
      scale 1 2.4
    }
  }
}
Wall {
  translation 3.5 0 1
  name "wall(34)"
  size 1 0.4 0.02
  appearance Roughcast {
    colorOverride 1 1 0
    textureTransform TextureTransform {
      scale 1 2.4
    }
  }
}
Wall {
  translation 3.5 0 -1
  name "wall(36)"
  size 1 0.4 0.02
  appearance Roughcast {
    colorOverride 1 1 0
    textureTransform TextureTransform {
      scale 1 2.4
    }
  }
}
Wall {
  translation 3.5 0 -3
  name "wall(44)"
  size 1 0.4 0.02
  appearance Roughcast {
    colorOverride 1 1 0
    textureTransform TextureTransform {
      scale 1 2.4
    }
  }
}
Wall {
  translation 4.5 0 1
  name "wall(35)"
  size 1 0.4 0.02
  appearance Roughcast {
    colorOverride 1 1 0
    textureTransform TextureTransform {
      scale 1 2.4
    }
  }
}
Wall {
  translation 4.5 0 3
  name "wall(39)"
  size 1 0.4 0.02
  appearance Roughcast {
    colorOverride 1 1 0
    textureTransform TextureTransform {
      scale 1 2.4
    }
  }
}
Wall {
  translation 3.5 0 3
  name "wall(40)"
  size 1 0.4 0.02
  appearance Roughcast {
    colorOverride 1 1 0
    textureTransform TextureTransform {
      scale 1 2.4
    }
  }
}
Wall {
  translation 4.5 0 -1
  name "wall(37)"
  size 1 0.4 0.02
  appearance Roughcast {
    colorOverride 1 1 0
    textureTransform TextureTransform {
      scale 1 2.4
    }
  }
}
Wall {
  translation 0.5 0 -1
  name "wall(32)"
  size 1 0.4 0.02
  appearance Roughcast {
    colorOverride 1 1 0
    textureTransform TextureTransform {
      scale 1 2.4
    }
  }
}
Wall {
  translation 0.5 0 3
  name "wall(7)"
  size 1 0.4 0.02
  appearance Roughcast {
    colorOverride 1 1 0
    textureTransform TextureTransform {
      scale 1 2.4
    }
  }
}
Wall {
  translation -4 0 4.5
  rotation 0 1 0 1.5708
  name "wall(2)"
  size 1 0.4 0.02
  appearance Roughcast {
    colorOverride 1 1 0
    textureTransform TextureTransform {
      scale 1 2.4
    }
  }
}
Wall {
  translation -4 0 1.5
  rotation 0 1 0 1.5708
  name "wall(9)"
  size 1 0.4 0.02
  appearance Roughcast {
    colorOverride 1 1 0
    textureTransform TextureTransform {
      scale 1 2.4
    }
  }
}
Wall {
  translation -4 0 0.5
  rotation 0 1 0 1.5708
  name "wall(10)"
  size 1 0.4 0.02
  appearance Roughcast {
    colorOverride 1 1 0
    textureTransform TextureTransform {
      scale 1 2.4
    }
  }
}
Wall {
  translation -4 0 -2.5
  rotation 0 1 0 1.5708
  name "wall(19)"
  size 1 0.4 0.02
  appearance Roughcast {
    colorOverride 1 1 0
    textureTransform TextureTransform {
      scale 1 2.4
    }
  }
}
Wall {
  translation -4 0 -3.5
  rotation 0 1 0 1.5708
  name "wall(20)"
  size 1 0.4 0.02
  appearance Roughcast {
    colorOverride 1 1 0
    textureTransform TextureTransform {
      scale 1 2.4
    }
  }
}
Wall {
  translation -3 0 -0.5
  rotation 0 1 0 1.5708
  name "wall(12)"
  size 1 0.4 0.02
  appearance Roughcast {
    colorOverride 1 1 0
    textureTransform TextureTransform {
      scale 1 2.4
    }
  }
}
Wall {
  translation -3 0 -1.5
  rotation 0 1 0 1.5708
  name "wall(14)"
  size 1 0.4 0.02
  appearance Roughcast {
    colorOverride 1 1 0
    textureTransform TextureTransform {
      scale 1 2.4
    }
  }
}
Wall {
  translation -3 0 -4.5
  rotation 0 1 0 1.5708
  name "wall(22)"
  size 1 0.4 0.02
  appearance Roughcast {
    colorOverride 1 1 0
    textureTransform TextureTransform {
      scale 1 2.4
    }
  }
}
