#VRML_SIM R2021a utf8
WorldInfo {
  coordinateSystem "NUE"
}
Viewpoint {
  orientation -0.9996380423585636 -0.023244713845608306 -0.013545019297668845 1.4073124647405264
  position 3.07717287933767 4.12048456974703 4.589877889548049
}
TexturedBackground {
}
TexturedBackgroundLight {
}
RectangleArena {
  name "rectangle arena(1)"
  floorSize 10 10
  floorTileSize 2 2
  wallHeight 0.5
}
Robot {
  translation 3.39928 0 3.3687
  children [
    Laptop {
      rotation 0 1 0 3.14159
    }
  ]
  name "robot(1)"
  recognitionColors [
    1 0 0
  ]
}
DEF mybot Robot {
  translation 0.550552 0.07 -0.377609
  children [
    DEF WHEEL HingeJoint {
      jointParameters HingeJointParameters {
        anchor 0.06 0 -0.05
      }
      device [
        RotationalMotor {
        }
      ]
      endPoint DEF Wheels Solid {
        translation 0.06 0 -0.05
        rotation 0 0 1 1.5708
        children [
          DEF Wheel Shape {
            appearance PBRAppearance {
              baseColor 1 1 0
            }
            geometry Cylinder {
              height 0.02
              radius 0.04
            }
          }
        ]
        name "solid(3)"
        boundingObject USE Wheel
        physics Physics {
        }
      }
    }
    DEF WHEEL HingeJoint {
      jointParameters HingeJointParameters {
        anchor 0.06 0 -0.05
      }
      device [
        RotationalMotor {
        }
      ]
      endPoint DEF Wheels Solid {
        translation -0.06 0 -0.05
        rotation 0 0 1 1.5708
        children [
          DEF Wheel Shape {
            appearance PBRAppearance {
              baseColor 1 1 0
            }
            geometry Cylinder {
              height 0.02
              radius 0.04
            }
          }
        ]
        name "solid(2)"
        boundingObject USE Wheel
        physics Physics {
        }
      }
    }
    DEF WHEEL HingeJoint {
      jointParameters HingeJointParameters {
        anchor 0.06 0 -0.05
      }
      device [
        RotationalMotor {
        }
      ]
      endPoint DEF Wheels Solid {
        translation -0.06 0 0.05
        rotation 0 0 1 1.5708
        children [
          DEF Wheel Shape {
            appearance PBRAppearance {
              baseColor 1 1 0
            }
            geometry Cylinder {
              height 0.02
              radius 0.04
            }
          }
        ]
        name "solid(1)"
        boundingObject USE Wheel
        physics Physics {
        }
      }
    }
    DEF WHEEL HingeJoint {
      jointParameters HingeJointParameters {
        anchor 0.06 0 -0.05
      }
      device [
        RotationalMotor {
        }
      ]
      endPoint DEF Wheels Solid {
        translation 0.06 0 0.05
        rotation 0 0 1 1.5708
        children [
          DEF Wheel Shape {
            appearance PBRAppearance {
              baseColor 1 1 0
            }
            geometry Cylinder {
              height 0.02
              radius 0.04
            }
          }
        ]
        boundingObject USE Wheel
        physics Physics {
        }
      }
    }
    DEF BODY Shape {
      appearance PBRAppearance {
        baseColor 1 0 1
      }
      geometry Box {
        size 0.1 0.03 0.2
      }
    }
  ]
  boundingObject USE BODY
  physics Physics {
  }
}
E-puck {
  translation 3.3995 0 4.12617
  controller "intermidiateepuck"
  turretSlot [
    Camera {
      name "camera_on_turret"
      recognitionColors [
        1 0 0
      ]
    }
    RobotisLds01 {
    }
  ]
}
Ball {
  translation 0.269182 0.0325 4.29364
  color 1 1 1
}
AdvertisingBoard {
  translation -2.08113 0 4.5221
  rotation 0 1 0 1.5708
  frontTexture [
    "textures/roughcast.jpg"
  ]
  recognitionColors [
    1 1 1
  ]
  displayBackLight TRUE
  displayWidth 0.25
  displayHeight 0.4
  frameThickness 0.1
}
Wall {
  translation 1 0 4.5
  rotation 0 1 0 1.5708
  name "wall(3)"
  size 1 0.4 0.02
  appearance Roughcast {
    colorOverride 1 1 0
    textureTransform TextureTransform {
      scale 1 2.4
    }
  }
}
Wall {
  translation 1 0 3.5
  rotation 0 1 0 1.5708
  name "wall(8)"
  size 1 0.4 0.02
  appearance Roughcast {
    colorOverride 1 1 0
    textureTransform TextureTransform {
      scale 1 2.4
    }
  }
}
Wall {
  translation 1 0 0.5
  rotation 0 1 0 1.5708
  name "wall(18)"
  size 1 0.4 0.02
  appearance Roughcast {
    colorOverride 1 1 0
    textureTransform TextureTransform {
      scale 1 2.4
    }
  }
}
Wall {
  translation -1 0 -4.5
  rotation 0 1 0 1.5708
  name "wall(24)"
  size 1 0.4 0.02
  appearance Roughcast {
    colorOverride 1 1 0
    textureTransform TextureTransform {
      scale 1 2.4
    }
  }
}
Wall {
  translation -1 0 -3.5
  rotation 0 1 0 1.5708
  name "wall(25)"
  size 1 0.4 0.02
  appearance Roughcast {
    colorOverride 1 1 0
    textureTransform TextureTransform {
      scale 1 2.4
    }
  }
}
Wall {
  translation -1 0 -2.5
  rotation 0 1 0 1.5708
  name "wall(28)"
  size 1 0.4 0.02
  appearance Roughcast {
    colorOverride 1 1 0
    textureTransform TextureTransform {
      scale 1 2.4
    }
  }
}
Wall {
  translation 1 0 -2.5
  rotation 0 1 0 1.5708
  name "wall(29)"
  size 1 0.4 0.02
  appearance Roughcast {
    colorOverride 1 1 0
    textureTransform TextureTransform {
      scale 1 2.4
    }
  }
}
Wall {
  translation -1 0 3.5
  rotation 0 1 0 1.5708
  name "wall(5)"
  size 1 0.4 0.02
  appearance Roughcast {
    colorOverride 1 1 0
    textureTransform TextureTransform {
      scale 1 2.4
    }
  }
}
Wall {
  translation -1 0 0.5
  rotation 0 1 0 1.5708
  name "wall(15)"
  size 1 0.4 0.02
  appearance Roughcast {
    colorOverride 1 1 0
    textureTransform TextureTransform {
      scale 1 2.4
    }
  }
}
Wall {
  translation 3 0 -0.5
  rotation 0 1 0 1.5708
  name "wall(38)"
  size 1 0.4 0.02
  appearance Roughcast {
    colorOverride 1 1 0
    textureTransform TextureTransform {
      scale 1 2.4
    }
  }
}
Wall {
  translation 3 0 -4.5
  rotation 0 1 0 1.5708
  name "wall(42)"
  size 1 0.4 0.02
  appearance Roughcast {
    colorOverride 1 1 0
    textureTransform TextureTransform {
      scale 1 2.4
    }
  }
}
Wall {
  translation 3 0 -3.5
  rotation 0 1 0 1.5708
  name "wall(43)"
  size 1 0.4 0.02
  appearance Roughcast {
    colorOverride 1 1 0
    textureTransform TextureTransform {
      scale 1 2.4
    }
  }
}
Wall {
  translation 3 0 3.5
  rotation 0 1 0 1.5708
  name "wall(41)"
  size 1 0.4 0.02
  appearance Roughcast {
    colorOverride 1 1 0
    textureTransform TextureTransform {
      scale 1 2.4
    }
  }
}
Wall {
  translation -1 0 -0.5
  rotation 0 1 0 1.5708
  name "wall(31)"
  size 1 0.4 0.02
  appearance Roughcast {
    colorOverride 1 1 0
    textureTransform TextureTransform {
      scale 1 2.4
    }
  }
}
Wall {
  translation -4.5 0 3
  name "wall(1)"
  size 1 0.4 0.02
  appearance Roughcast {
    colorOverride 1 1 0
    textureTransform TextureTransform {
      scale 1 2.4
    }
  }
}
Wall {
  translation -1.5 0 4
  name "wall(4)"
  size 1 0.4 0.02
  appearance Roughcast {
    colorOverride 1 1 0
    textureTransform TextureTransform {
      scale 1 2.4
    }
  }
}
Wall {
  translation -3.5 0 0
  name "wall(11)"
  size 1 0.4 0.02
  appearance Roughcast {
    colorOverride 1 1 0
    textureTransform TextureTransform {
      scale 1 2.4
    }
  }
}
Wall {
  translation -3.5 0 -2
  name "wall(13)"
  size 1 0.4 0.02
  appearance Roughcast {
    colorOverride 1 1 0
    textureTransform TextureTransform {
      scale 1 2.4
    }
  }
}
Wall {
  translation -3.5 0 -4
  name "wall(21)"
  size 1 0.4 0.02
  appearance Roughcast {
    colorOverride 1 1 0
    textureTransform TextureTransform {
      scale 1 2.4
    }
  }
}
Wall {
  translation -0.5 0 3
  name "wall(6)"
  size 1 0.4 0.02
  appearance Roughcast {
    colorOverride 1 1 0
    textureTransform TextureTransform {
      scale 1 2.4
    }
  }
}
Wall {
  translation -0.5 0 1
  name "wall(17)"
  size 1 0.4 0.02
  appearance Roughcast {
    colorOverride 1 1 0
    textureTransform TextureTransform {
      scale 1 2.4
    }
  }
}
Wall {
  translation -0.5 0 -1
  name "wall(33)"
  size 1 0.4 0.02
  appearance Roughcast {
    colorOverride 1 1 0
    textureTransform TextureTransform {
      scale 1 2.4
    }
  }
}
Wall {
  translation -0.5 0 -2
  name "wall(26)"
  size 1 0.4 0.02
  appearance Roughcast {
    colorOverride 1 1 0
    textureTransform TextureTransform {
      scale 1 2.4
    }
  }
}
Wall {
  translation 0.5 0 -2
  name "wall(27)"
  size 1 0.4 0.02
  appearance Roughcast {
    colorOverride 1 1 0
    textureTransform TextureTransform {
      scale 1 2.4
    }
  }
}
Wall {
  translation 1.5 0 -3
  name "wall(30)"
  size 1 0.4 0.02
  appearance Roughcast {
    colorOverride 1 1 0
    textureTransform TextureTransform {
      scale 1 2.4
    }
  }
}
Wall {
  translation 0.5 0 1
  name "wall(16)"
  size 1 0.4 0.02
  appearance Roughcast {
    colorOverride 1 1 0
    textureTransform TextureTransform {
      scale 1 2.4
    }
  }
}
Wall {
  translation 3.5 0 1
  name "wall(34)"
  size 1 0.4 0.02
  appearance Roughcast {
    colorOverride 1 1 0
    textureTransform TextureTransform {
      scale 1 2.4
    }
  }
}
Wall {
  translation 3.5 0 -1
  name "wall(36)"
  size 1 0.4 0.02
  appearance Roughcast {
    colorOverride 1 1 0
    textureTransform TextureTransform {
      scale 1 2.4
    }
  }
}
Wall {
  translation 3.5 0 -3
  name "wall(44)"
  size 1 0.4 0.02
  appearance Roughcast {
    colorOverride 1 1 0
    textureTransform TextureTransform {
      scale 1 2.4
    }
  }
}
Wall {
  translation 4.5 0 1
  name "wall(35)"
  size 1 0.4 0.02
  appearance Roughcast {
    colorOverride 1 1 0
    textureTransform TextureTransform {
      scale 1 2.4
    }
  }
}
Wall {
  translation 4.5 0 3
  name "wall(39)"
  size 1 0.4 0.02
  appearance Roughcast {
    colorOverride 1 1 0
    textureTransform TextureTransform {
      scale 1 2.4
    }
  }
}
Wall {
  translation 3.5 0 3
  name "wall(40)"
  size 1 0.4 0.02
  appearance Roughcast {
    colorOverride 1 1 0
    textureTransform TextureTransform {
      scale 1 2.4
    }
  }
}
Wall {
  translation 4.5 0 -1
  name "wall(37)"
  size 1 0.4 0.02
  appearance Roughcast {
    colorOverride 1 1 0
    textureTransform TextureTransform {
      scale 1 2.4
    }
  }
}
Wall {
  translation 0.5 0 -1
  name "wall(32)"
  size 1 0.4 0.02
  appearance Roughcast {
    colorOverride 1 1 0
    textureTransform TextureTransform {
      scale 1 2.4
    }
  }
}
Wall {
  translation 0.5 0 3
  name "wall(7)"
  size 1 0.4 0.02
  appearance Roughcast {
    colorOverride 1 1 0
    textureTransform TextureTransform {
      scale 1 2.4
    }
  }
}
Wall {
  translation -4 0 4.5
  rotation 0 1 0 1.5708
  name "wall(2)"
  size 1 0.4 0.02
  appearance Roughcast {
    colorOverride 1 1 0
    textureTransform TextureTransform {
      scale 1 2.4
    }
  }
}
Wall {
  translation -4 0 1.5
  rotation 0 1 0 1.5708
  name "wall(9)"
  size 1 0.4 0.02
  appearance Roughcast {
    colorOverride 1 1 0
    textureTransform TextureTransform {
      scale 1 2.4
    }
  }
}
Wall {
  translation -4 0 0.5
  rotation 0 1 0 1.5708
  name "wall(10)"
  size 1 0.4 0.02
  appearance Roughcast {
    colorOverride 1 1 0
    textureTransform TextureTransform {
      scale 1 2.4
    }
  }
}
Wall {
  translation -4 0 -2.5
  rotation 0 1 0 1.5708
  name "wall(19)"
  size 1 0.4 0.02
  appearance Roughcast {
    colorOverride 1 1 0
    textureTransform TextureTransform {
      scale 1 2.4
    }
  }
}
Wall {
  translation -4 0 -3.5
  rotation 0 1 0 1.5708
  name "wall(20)"
  size 1 0.4 0.02
  appearance Roughcast {
    colorOverride 1 1 0
    textureTransform TextureTransform {
      scale 1 2.4
    }
  }
}
Wall {
  translation -3 0 -0.5
  rotation 0 1 0 1.5708
  name "wall(12)"
  size 1 0.4 0.02
  appearance Roughcast {
    colorOverride 1 1 0
    textureTransform TextureTransform {
      scale 1 2.4
    }
  }
}
Wall {
  translation -3 0 -1.5
  rotation 0 1 0 1.5708
  name "wall(14)"
  size 1 0.4 0.02
  appearance Roughcast {
    colorOverride 1 1 0
    textureTransform TextureTransform {
      scale 1 2.4
    }
  }
}
Wall {
  translation -3 0 -4.5
  rotation 0 1 0 1.5708
  name "wall(22)"
  size 1 0.4 0.02
  appearance Roughcast {
    colorOverride 1 1 0
    textureTransform TextureTransform {
      scale 1 2.4
    }
  }
}
